Traceback (most recent call last):
  File "/Users/guestadmin/Library/Caches/pypoetry/virtualenvs/teach-python-_R03MHmW-py3.6/lib/python3.6/site-packages/jupyter_cache/executors/utils.py", line 56, in single_nb_execution
    record_timing=False,
  File "/Users/guestadmin/Library/Caches/pypoetry/virtualenvs/teach-python-_R03MHmW-py3.6/lib/python3.6/site-packages/nbclient/client.py", line 1087, in execute
    return NotebookClient(nb=nb, resources=resources, km=km, **kwargs).execute()
  File "/Users/guestadmin/Library/Caches/pypoetry/virtualenvs/teach-python-_R03MHmW-py3.6/lib/python3.6/site-packages/nbclient/util.py", line 74, in wrapped
    return just_run(coro(*args, **kwargs))
  File "/Users/guestadmin/Library/Caches/pypoetry/virtualenvs/teach-python-_R03MHmW-py3.6/lib/python3.6/site-packages/nbclient/util.py", line 53, in just_run
    return loop.run_until_complete(coro)
  File "/usr/local/opt/python/Frameworks/Python.framework/Versions/3.6/lib/python3.6/asyncio/base_events.py", line 468, in run_until_complete
    return future.result()
  File "/Users/guestadmin/Library/Caches/pypoetry/virtualenvs/teach-python-_R03MHmW-py3.6/lib/python3.6/site-packages/nbclient/client.py", line 541, in async_execute
    cell, index, execution_count=self.code_cells_executed + 1
  File "/Users/guestadmin/Library/Caches/pypoetry/virtualenvs/teach-python-_R03MHmW-py3.6/lib/python3.6/site-packages/nbclient/client.py", line 832, in async_execute_cell
    self._check_raise_for_error(cell, exec_reply)
  File "/Users/guestadmin/Library/Caches/pypoetry/virtualenvs/teach-python-_R03MHmW-py3.6/lib/python3.6/site-packages/nbclient/client.py", line 740, in _check_raise_for_error
    raise CellExecutionError.from_cell_and_msg(cell, exec_reply['content'])
nbclient.exceptions.CellExecutionError: An error occurred while executing the following cell:
------------------
read_file('some_file.txt')
------------------

[0;31m---------------------------------------------------------------------------[0m
[0;31mFileNotFoundError[0m                         Traceback (most recent call last)
[0;32m<ipython-input-3-4de66af3dd44>[0m in [0;36m<module>[0;34m[0m
[0;32m----> 1[0;31m [0mread_file[0m[0;34m([0m[0;34m'some_file.txt'[0m[0;34m)[0m[0;34m[0m[0m
[0m
[0;32m<ipython-input-1-2d94c9561f45>[0m in [0;36mread_file[0;34m(file_name)[0m
[1;32m      1[0m [0;32mdef[0m [0mread_file[0m[0;34m([0m[0mfile_name[0m[0;34m)[0m[0;34m:[0m[0;34m[0m[0m
[0;32m----> 2[0;31m     [0;32mwith[0m [0mopen[0m[0;34m([0m[0mfile_name[0m[0;34m,[0m [0;34m'r'[0m[0;34m)[0m [0;32mas[0m [0mf[0m[0;34m:[0m[0;34m[0m[0m
[0m[1;32m      3[0m         [0;32mreturn[0m [0;34m[[0m[0mline[0m[0;34m.[0m[0mrstrip[0m[0;34m([0m[0;34m)[0m [0;32mfor[0m [0mline[0m [0;32min[0m [0mf[0m[0;34m][0m[0;34m[0m[0m
[1;32m      4[0m [0;34m[0m[0m
[1;32m      5[0m [0;32mdef[0m [0mread_file_improved[0m[0;34m([0m[0mfile_name[0m[0;34m)[0m[0;34m:[0m[0;34m[0m[0m

[0;31mFileNotFoundError[0m: [Errno 2] No such file or directory: 'some_file.txt'
FileNotFoundError: [Errno 2] No such file or directory: 'some_file.txt'

